Workbook

Sheet 00_チェック
A1: 研究室HP 入力データ｜入力チェック
A2: 各シートの黄色いセルを確認してください。「入力完了」になれば、サンプルのまま残っている必須項目はありません。 このファイルはGitHubに保存される可能性があります。公開されても問題ない情報だけを記入してください。
A4: 全体判定 | B4: =IF(OR(C7="ERROR: 要編集あり",C8="ERROR: 要編集あり",C9="ERROR: 要編集あり",C10="ERROR: 要編集あり",C11="ERROR: 要編集あり",C12="ERROR: 要編集あり",C13="ERROR: 要編集あり",C14="ERROR: 要編集あり",C15="ERROR: 要編集あり"),"入力未完了","入力完了") -> 入力未完了
A6: No. | B6: シート | C6: 状態 | D6: 内容 | E6: 確認ポイント
A7: 01 | B7: 01_基本情報 | C7: ='01_基本情報'!C4 -> ERROR: 要編集あり | D7: サイト全体 | E7: タイトル・検索結果の説明・研究室名
A8: 02 | B8: 02_NEWS | C8: ='02_NEWS'!C5 -> ERROR: 要編集あり | D8: NEWS | E8: 不要なら「表示しない」
A9: 03 | B9: 03_研究テーマ | C9: ='03_研究テーマ'!C5 -> ERROR: 要編集あり | D9: 研究テーマ | E9: 画像の上下で本文を分ける場合は①②を使い分ける
A10: 04 | B10: 04_研究室のモットー | C10: ='04_研究室のモットー'!C5 -> ERROR: 要編集あり | D10: 研究室のモットー | E10: 名称変更・削除も可能
A11: 05 | B11: 05_研究室メンバー | C11: ='05_研究室メンバー'!C5 -> ERROR: 要編集あり | D11: 研究室メンバー | E11: 予備行を使って追加可能
A12: 06 | B12: 06_プロフィール | C12: ='06_プロフィール'!C5 -> ERROR: 要編集あり | D12: プロフィール | E12: 氏名・経歴・外部リンク
A13: 07 | B13: 07_論文・研究発表 | C13: ='07_論文・研究発表'!C5 -> ERROR: 要編集あり | D13: 論文・研究発表 | E13: 分類の削除・名称変更も可能
A14: 08 | B14: 08_Contact | C14: ='08_Contact'!C5 -> ERROR: 要編集あり | D14: Contact | E14: Google Map設定を含む
A15: 09 | B15: 09_フッター | C15: ='09_フッター'!C4 -> ERROR: 要編集あり | D15: フッター | E15: コピーライト
A17: セクションを「表示しない」にした場合は、本文だけでなく左メニュー・現在位置表示・そのセクションに連動する機能も含めて削除・調整する前提です。HTMLの一部分だけを消すのではなく、CodexにこのExcel全体を渡して反映させてください。

Sheet 01_基本情報
A1: 研究室HP 入力データ｜基本情報
A2: 黄色いセルをサンプルから自分の研究室の内容へ書き換えてください。
A4: セクション判定 | C4: =IF(OR(C7="要編集",C7="未入力",C8="要編集",C8="未入力",C9="要編集",C9="未入力",C10="要編集",C10="未入力"),"ERROR: 要編集あり","OK") -> ERROR: 要編集あり
A6: 項目 | B6: 入力内容 | C6: 判定 | D6: 何に使うか | E6: 補足
A7: ページタイトル | B7: 研究者WEBサイトテンプレート | C7: =IF(B7="","未入力",IF(B7="研究者WEBサイトテンプレート","要編集","OK")) -> 要編集 | D7: ブラウザのタブや検索結果のタイトル | E7: 研究室名・大学名が分かる表記にします。
A8: 検索結果の説明（ディスクリプション） | B8: 研究者WEBサイトテンプレート | C8: =IF(B8="","未入力",IF(B8="研究者WEBサイトテンプレート","要編集","OK")) -> 要編集 | D8: Google等で検索されたときに表示される短い説明文 | E8: 研究分野や研究室の特徴が短く伝わる文章にします。
A9: 研究室名（日本語） | B9: コミュニケーションデザインラボ - 佐藤研究室 | C9: =IF(B9="","未入力",IF(B9="コミュニケーションデザインラボ - 佐藤研究室","要編集","OK")) -> 要編集 | D9: ページ上部の研究室名
A10: 研究室名（英語） | B10: Communication Design Laboratory | C10: =IF(B10="","未入力",IF(B10="Communication Design Laboratory","要編集","OK")) -> 要編集 | D10: ページ上部の英語表記

Sheet 02_NEWS
A1: 研究室HP 入力データ｜NEWS
A2: このセクションを表示する | B2: はい | C2: 「いいえ」にすると、このセクションと左メニューの項目を削除します。
A3: セクション名 | B3: NEWS | C3: 名称を変える場合だけ編集してください。ページ見出しと左メニューの名称を同じ内容に変更します。
A5: セクション判定 | C5: =IF(B2="いいえ","削除予定",IF(COUNTIF(E10:E21,"要編集")+COUNTIF(E10:E21,"未入力")>0,"ERROR: 要編集あり","OK")) -> ERROR: 要編集あり
A7: NEWS自体が不要なら「このセクションを表示する」を「いいえ」にしてください。リンクが不要なニュースはリンクURLを空欄のままで構いません。
A9: No. | B9: 日付 | C9: 本文 | D9: リンクURL | E9: 判定
A10: 1 | B10: 2023.10.05 | C10: [学年]の[研究室のメンバーの名前]君が[学会の名前]で[賞の名前]を受賞しました。 | E10: =IF($B$2="いいえ","削除予定",IF(AND(B10="",C10="",D10=""),"削除予定",IF(AND(B10="2023.10.05",C10="[学年]の[研究室のメンバーの名前]君が[学会の名前]で[賞の名前]を受賞しました。"),"要編集",IF(OR(B10="",C10=""),"未入力","OK")))) -> 要編集
A11: 2 | B11: 2023.10.05 | C11: [研究室名]では新しい研究プロジェクトを開始しました。このプロジェクトでは[研究のテーマや目的]に焦点を当てています。 | E11: =IF($B$2="いいえ","削除予定",IF(AND(B11="",C11="",D11=""),"削除予定",IF(AND(B11="2023.10.05",C11="[研究室名]では新しい研究プロジェクトを開始しました。このプロジェクトでは[研究のテーマや目的]に焦点を当てています。"),"要編集",IF(OR(B11="",C11=""),"未入力","OK")))) -> 要編集
A12: 3 | B12: 2023.10.05 | C12: 新しい論文が[学術雑誌の名前]に掲載されました。この論文では[論文の主題や重要な発見]について論じています。 | E12: =IF($B$2="いいえ","削除予定",IF(AND(B12="",C12="",D12=""),"削除予定",IF(AND(B12="2023.10.05",C12="新しい論文が[学術雑誌の名前]に掲載されました。この論文では[論文の主題や重要な発見]について論じています。"),"要編集",IF(OR(B12="",C12=""),"未入力","OK")))) -> 要編集
A13: 4 | B13: 2023.10.05 | C13: 当研究室は[研究テーマ]に関する共同研究を[他の研究機関や企業の名前]と開始しました。この共同研究により[期待される成果や目的]を目指します。 | E13: =IF($B$2="いいえ","削除予定",IF(AND(B13="",C13="",D13=""),"削除予定",IF(AND(B13="2023.10.05",C13="当研究室は[研究テーマ]に関する共同研究を[他の研究機関や企業の名前]と開始しました。この共同研究により[期待される成果や目的]を目指します。"),"要編集",IF(OR(B13="",C13=""),"未入力","OK")))) -> 要編集
A14: 5 | B14: 2023.10.05 | C14: [学年]の[メンバーの名前]君が[学会の名前]において[講演の主題]というテーマで基調講演を行いました。 | E14: =IF($B$2="いいえ","削除予定",IF(AND(B14="",C14="",D14=""),"削除予定",IF(AND(B14="2023.10.05",C14="[学年]の[メンバーの名前]君が[学会の名前]において[講演の主題]というテーマで基調講演を行いました。"),"要編集",IF(OR(B14="",C14=""),"未入力","OK")))) -> 要編集
A15: 6 | E15: =IF($B$2="いいえ","削除予定",IF(AND(B15="",C15="",D15=""),"削除予定",IF(OR(B15="",C15=""),"未入力","OK"))) -> 削除予定
A16: 7 | E16: =IF($B$2="いいえ","削除予定",IF(AND(B16="",C16="",D16=""),"削除予定",IF(OR(B16="",C16=""),"未入力","OK"))) -> 削除予定
A17: 8 | E17: =IF($B$2="いいえ","削除予定",IF(AND(B17="",C17="",D17=""),"削除予定",IF(OR(B17="",C17=""),"未入力","OK"))) -> 削除予定
A18: 9 | E18: =IF($B$2="いいえ","削除予定",IF(AND(B18="",C18="",D18=""),"削除予定",IF(OR(B18="",C18=""),"未入力","OK"))) -> 削除予定
A19: 10 | E19: =IF($B$2="いいえ","削除予定",IF(AND(B19="",C19="",D19=""),"削除予定",IF(OR(B19="",C19=""),"未入力","OK"))) -> 削除予定
A20: 11 | E20: =IF($B$2="いいえ","削除予定",IF(AND(B20="",C20="",D20=""),"削除予定",IF(OR(B20="",C20=""),"未入力","OK"))) -> 削除予定
A21: 12 | E21: =IF($B$2="いいえ","削除予定",IF(AND(B21="",C21="",D21=""),"削除予定",IF(OR(B21="",C21=""),"未入力","OK"))) -> 削除予定

Sheet 03_研究テーマ
A1: 研究室HP 入力データ｜研究テーマ
A2: このセクションを表示する | B2: はい | C2: 「いいえ」にすると、このセクションと左メニューの項目を削除します。
A3: セクション名 | B3: 研究テーマ | C3: 名称を変える場合だけ編集してください。ページ見出しと左メニューの名称を同じ内容に変更します。
A5: セクション判定 | C5: =IF(B2="いいえ","削除予定",IF(COUNTIF(E10:E17,"要編集")+COUNTIF(E10:E17,"未入力")>0,"ERROR: 要編集あり","OK")) -> ERROR: 要編集あり
A7: 本文①は画像の上、本文②は画像の下に表示する文章です。画像を文章の途中に置くときだけ①と②を分けて使います。画像を文章の上または下に置く場合、または画像を使わない場合は、本文①だけ（または本文②だけ）でも構いません。
A9: No. | B9: 見出し | C9: 本文①（画像の上） | D9: 本文②（画像の下） | E9: 判定
A10: 1 | B10: 人工知能における機械学習アルゴリズムの最適化 | C10: 当研究では、機械学習アルゴリズムの精度と効率を向上させる方法を探求しています。特に、データの前処理、特徴選択、モデル構築の各ステップでの最新の技術を組み合わせることに重点を置いています。 | D10: この研究により、さまざまな分野での応用が可能なより高度な人工知能システムの開発を目指しています。例えば、医療診断、金融市場分析、自動運転車の技術など、社会に大きな影響を与える分野に貢献することを期待しています。 | E10: =IF($B$2="いいえ","削除予定",IF(AND(B10="",C10="",D10=""),"削除予定",IF(AND(B10="人工知能における機械学習アルゴリズムの最適化",C10="当研究では、機械学習アルゴリズムの精度と効率を向上させる方法を探求しています。特に、データの前処理、特徴選択、モデル構築の各ステップでの最新の技術を組み合わせることに重点を置いています。",D10="この研究により、さまざまな分野での応用が可能なより高度な人工知能システムの開発を目指しています。例えば、医療診断、金融市場分析、自動運転車の技術など、社会に大きな影響を与える分野に貢献することを期待しています。"),"要編集",IF(OR(B10="",AND(C10="",D10="")),"未入力","OK")))) -> 要編集
A11: 2 | B11: 再生可能エネルギー源の開発と利用 | C11: 本研究では、太陽光、風力、地熱などの再生可能エネルギー源の効率的な活用方法を探求しています。これには、エネルギー変換の効率向上やコスト削減の技術開発が含まれます。 また、再生可能エネルギーの普及を促進するための社会的、経済的な戦略についても研究しています。持続可能なエネルギーシステムの構築に向けて、政策提言や公共啓発活動にも力を入れています。 | E11: =IF($B$2="いいえ","削除予定",IF(AND(B11="",C11="",D11=""),"削除予定",IF(AND(B11="再生可能エネルギー源の開発と利用",C11="本研究では、太陽光、風力、地熱などの再生可能エネルギー源の効率的な活用方法を探求しています。これには、エネルギー変換の効率向上やコスト削減の技術開発が含まれます。 また、再生可能エネルギーの普及を促進するための社会的、経済的な戦略についても研究しています。持続可能なエネルギーシステムの構築に向けて、政策提言や公共啓発活動にも力を入れています。",D11=""),"要編集",IF(OR(B11="",AND(C11="",D11="")),"未入力","OK")))) -> 要編集
A12: 3 | B12: ヒトの健康と疾患に関するバイオテクノロジーの応用 | C12: 当研究室では、遺伝子編集技術や幹細胞療法など、最先端のバイオテクノロジーを用いた疾患治療法の開発に取り組んでいます。特に、がんや遺伝性疾患の治療に焦点を当てています。 さらに、これらの治療法の臨床応用に向けて、安全性と効果の評価を行っています。患者のQOL向上に貢献するとともに、新しい医療技術の普及に向けた研究も進めています。 | E12: =IF($B$2="いいえ","削除予定",IF(AND(B12="",C12="",D12=""),"削除予定",IF(AND(B12="ヒトの健康と疾患に関するバイオテクノロジーの応用",C12="当研究室では、遺伝子編集技術や幹細胞療法など、最先端のバイオテクノロジーを用いた疾患治療法の開発に取り組んでいます。特に、がんや遺伝性疾患の治療に焦点を当てています。 さらに、これらの治療法の臨床応用に向けて、安全性と効果の評価を行っています。患者のQOL向上に貢献するとともに、新しい医療技術の普及に向けた研究も進めています。",D12=""),"要編集",IF(OR(B12="",AND(C12="",D12="")),"未入力","OK")))) -> 要編集
A13: 4 | E13: =IF($B$2="いいえ","削除予定",IF(AND(B13="",C13="",D13=""),"削除予定",IF(OR(B13="",AND(C13="",D13="")),"未入力","OK"))) -> 削除予定
A14: 5 | E14: =IF($B$2="いいえ","削除予定",IF(AND(B14="",C14="",D14=""),"削除予定",IF(OR(B14="",AND(C14="",D14="")),"未入力","OK"))) -> 削除予定
A15: 6 | E15: =IF($B$2="いいえ","削除予定",IF(AND(B15="",C15="",D15=""),"削除予定",IF(OR(B15="",AND(C15="",D15="")),"未入力","OK"))) -> 削除予定
A16: 7 | E16: =IF($B$2="いいえ","削除予定",IF(AND(B16="",C16="",D16=""),"削除予定",IF(OR(B16="",AND(C16="",D16="")),"未入力","OK"))) -> 削除予定
A17: 8 | E17: =IF($B$2="いいえ","削除予定",IF(AND(B17="",C17="",D17=""),"削除予定",IF(OR(B17="",AND(C17="",D17="")),"未入力","OK"))) -> 削除予定

Sheet 04_研究室のモットー
A1: 研究室HP 入力データ｜研究室のモットー
A2: このセクションを表示する | B2: はい | C2: 「いいえ」にすると、このセクションと左メニューの項目を削除します。
A3: セクション名 | B3: 研究室のモットー | C3: 名称を変える場合だけ編集してください。ページ見出しと左メニューの名称を同じ内容に変更します。
A5: セクション判定 | C5: =IF(B2="いいえ","削除予定",IF(COUNTIF(D10:D15,"要編集")+COUNTIF(D10:D15,"未入力")>0,"ERROR: 要編集あり","OK")) -> ERROR: 要編集あり
A7: 「研究室のモットー」というセクション名自体も変更できます。変更した場合は、ページ見出しと左メニューの名称も同じ内容に変更されます。
A9: No. | B9: 表題 | C9: 本文 | D9: 判定
A10: 1 | B10: 知識の探求と社会への貢献 | C10: 私たちの研究室は、最先端の科学技術を追求し、その成果を社会に還元することをミッションとしています。学術的な探究心と実社会への応用を通じて、世界に貢献することを目指します。 | D10: =IF($B$2="いいえ","削除予定",IF(AND(B10="",C10=""),"削除予定",IF(AND(B10="知識の探求と社会への貢献",C10="私たちの研究室は、最先端の科学技術を追求し、その成果を社会に還元することをミッションとしています。学術的な探究心と実社会への応用を通じて、世界に貢献することを目指します。"),"要編集",IF(OR(B10="",C10=""),"未入力","OK")))) -> 要編集
A11: 2 | B11: 革新と協力の精神 | C11: 私たちは、研究の革新を目指し、異なる分野や文化の専門家と積極的に協力することを重視します。多様なアイデアと視点を統合することで、新しい発見とソリューションを生み出すことを目標としています。 | D11: =IF($B$2="いいえ","削除予定",IF(AND(B11="",C11=""),"削除予定",IF(AND(B11="革新と協力の精神",C11="私たちは、研究の革新を目指し、異なる分野や文化の専門家と積極的に協力することを重視します。多様なアイデアと視点を統合することで、新しい発見とソリューションを生み出すことを目標としています。"),"要編集",IF(OR(B11="",C11=""),"未入力","OK")))) -> 要編集
A12: 3 | D12: =IF($B$2="いいえ","削除予定",IF(AND(B12="",C12=""),"削除予定",IF(OR(B12="",C12=""),"未入力","OK"))) -> 削除予定
A13: 4 | D13: =IF($B$2="いいえ","削除予定",IF(AND(B13="",C13=""),"削除予定",IF(OR(B13="",C13=""),"未入力","OK"))) -> 削除予定
A14: 5 | D14: =IF($B$2="いいえ","削除予定",IF(AND(B14="",C14=""),"削除予定",IF(OR(B14="",C14=""),"未入力","OK"))) -> 削除予定
A15: 6 | D15: =IF($B$2="いいえ","削除予定",IF(AND(B15="",C15=""),"削除予定",IF(OR(B15="",C15=""),"未入力","OK"))) -> 削除予定

Sheet 05_研究室メンバー
A1: 研究室HP 入力データ｜研究室メンバー
A2: このセクションを表示する | B2: はい | C2: 「いいえ」にすると、このセクションと左メニューの項目を削除します。
A3: セクション名 | B3: 研究室メンバー | C3: 名称を変える場合だけ編集してください。ページ見出しと左メニューの名称を同じ内容に変更します。
A5: セクション判定 | C5: =IF(B2="いいえ","削除予定",IF(COUNTIF(E10:E39,"要編集")+COUNTIF(E10:E39,"未入力")>0,"ERROR: 要編集あり","OK")) -> ERROR: 要編集あり
A7: 下に30行分の入力欄を用意しています。足りない場合は最終行の下へ行を追加して構いません。No.はExcel上の管理用なのでHTMLの表示には使いません。追加行が黄色でなくてもCodexは読み取れますが、判定式がない行は00_チェックの対象外になるため、まずは予備行を使ってください。
A9: No. | B9: 区分 | C9: 年度 | D9: 氏名・所属等 | E9: 判定
A10: 1 | B10: 博士後期課程 | D10: 佐藤 明子 (3年) | E10: =IF($B$2="いいえ","削除予定",IF(AND(B10="",C10="",D10=""),"削除予定",IF(AND(B10="博士後期課程",C10="",D10="佐藤 明子 (3年)"),"要編集",IF(OR(B10="",D10=""),"未入力","OK")))) -> 要編集
A11: 2 | B11: 博士後期課程 | D11: 田中 健一 (2年) | E11: =IF($B$2="いいえ","削除予定",IF(AND(B11="",C11="",D11=""),"削除予定",IF(AND(B11="博士後期課程",C11="",D11="田中 健一 (2年)"),"要編集",IF(OR(B11="",D11=""),"未入力","OK")))) -> 要編集
A12: 3 | B12: 博士後期課程 | D12: 鈴木 雅人 (1年) | E12: =IF($B$2="いいえ","削除予定",IF(AND(B12="",C12="",D12=""),"削除予定",IF(AND(B12="博士後期課程",C12="",D12="鈴木 雅人 (1年)"),"要編集",IF(OR(B12="",D12=""),"未入力","OK")))) -> 要編集
A13: 4 | B13: 博士前期課程 | D13: 伊藤 美咲 (2年) | E13: =IF($B$2="いいえ","削除予定",IF(AND(B13="",C13="",D13=""),"削除予定",IF(AND(B13="博士前期課程",C13="",D13="伊藤 美咲 (2年)"),"要編集",IF(OR(B13="",D13=""),"未入力","OK")))) -> 要編集
A14: 5 | B14: 博士前期課程 | D14: 中村 拓哉 (1年) | E14: =IF($B$2="いいえ","削除予定",IF(AND(B14="",C14="",D14=""),"削除予定",IF(AND(B14="博士前期課程",C14="",D14="中村 拓哉 (1年)"),"要編集",IF(OR(B14="",D14=""),"未入力","OK")))) -> 要編集
A15: 6 | B15: OB / OG | C15: 1978年度 | D15: 山田 花 (芦田先端技研株式会社) | E15: =IF($B$2="いいえ","削除予定",IF(AND(B15="",C15="",D15=""),"削除予定",IF(AND(B15="OB / OG",C15="1978年度",D15="山田 花 (芦田先端技研株式会社)"),"要編集",IF(OR(B15="",D15=""),"未入力","OK")))) -> 要編集
A16: 7 | B16: OB / OG | C16: 1978年度 | D16: 佐々木 一郎 (星明技術研究所 研究員) | E16: =IF($B$2="いいえ","削除予定",IF(AND(B16="",C16="",D16=""),"削除予定",IF(AND(B16="OB / OG",C16="1978年度",D16="佐々木 一郎 (星明技術研究所 研究員)"),"要編集",IF(OR(B16="",D16=""),"未入力","OK")))) -> 要編集
A17: 8 | B17: OB / OG | C17: 1979年度 | D17: 吉田 美香 (帝都大学 研究員) | E17: =IF($B$2="いいえ","削除予定",IF(AND(B17="",C17="",D17=""),"削除予定",IF(AND(B17="OB / OG",C17="1979年度",D17="吉田 美香 (帝都大学 研究員)"),"要編集",IF(OR(B17="",D17=""),"未入力","OK")))) -> 要編集
A18: 9 | B18: OB / OG | C18: 1979年度 | D18: 鈴木 陽一 (株式会社藍原エコエネルギー研究所) | E18: =IF($B$2="いいえ","削除予定",IF(AND(B18="",C18="",D18=""),"削除予定",IF(AND(B18="OB / OG",C18="1979年度",D18="鈴木 陽一 (株式会社藍原エコエネルギー研究所)"),"要編集",IF(OR(B18="",D18=""),"未入力","OK")))) -> 要編集
A19: 10 | E19: =IF($B$2="いいえ","削除予定",IF(AND(B19="",C19="",D19=""),"削除予定",IF(OR(B19="",D19=""),"未入力","OK"))) -> 削除予定
A20: 11 | E20: =IF($B$2="いいえ","削除予定",IF(AND(B20="",C20="",D20=""),"削除予定",IF(OR(B20="",D20=""),"未入力","OK"))) -> 削除予定
A21: 12 | E21: =IF($B$2="いいえ","削除予定",IF(AND(B21="",C21="",D21=""),"削除予定",IF(OR(B21="",D21=""),"未入力","OK"))) -> 削除予定
A22: 13 | E22: =IF($B$2="いいえ","削除予定",IF(AND(B22="",C22="",D22=""),"削除予定",IF(OR(B22="",D22=""),"未入力","OK"))) -> 削除予定
A23: 14 | E23: =IF($B$2="いいえ","削除予定",IF(AND(B23="",C23="",D23=""),"削除予定",IF(OR(B23="",D23=""),"未入力","OK"))) -> 削除予定
A24: 15 | E24: =IF($B$2="いいえ","削除予定",IF(AND(B24="",C24="",D24=""),"削除予定",IF(OR(B24="",D24=""),"未入力","OK"))) -> 削除予定
A25: 16 | E25: =IF($B$2="いいえ","削除予定",IF(AND(B25="",C25="",D25=""),"削除予定",IF(OR(B25="",D25=""),"未入力","OK"))) -> 削除予定
A26: 17 | E26: =IF($B$2="いいえ","削除予定",IF(AND(B26="",C26="",D26=""),"削除予定",IF(OR(B26="",D26=""),"未入力","OK"))) -> 削除予定
A27: 18 | E27: =IF($B$2="いいえ","削除予定",IF(AND(B27="",C27="",D27=""),"削除予定",IF(OR(B27="",D27=""),"未入力","OK"))) -> 削除予定
A28: 19 | E28: =IF($B$2="いいえ","削除予定",IF(AND(B28="",C28="",D28=""),"削除予定",IF(OR(B28="",D28=""),"未入力","OK"))) -> 削除予定
A29: 20 | E29: =IF($B$2="いいえ","削除予定",IF(AND(B29="",C29="",D29=""),"削除予定",IF(OR(B29="",D29=""),"未入力","OK"))) -> 削除予定
A30: 21 | E30: =IF($B$2="いいえ","削除予定",IF(AND(B30="",C30="",D30=""),"削除予定",IF(OR(B30="",D30=""),"未入力","OK"))) -> 削除予定
... A39: 30 | E39: =IF($B$2="いいえ","削除予定",IF(AND(B39="",C39="",D39=""),"削除予定",IF(OR(B39="",D39=""),"未入力","OK"))) -> 削除予定

Sheet 06_プロフィール
A1: 研究室HP 入力データ｜プロフィール
A2: このセクションを表示する | B2: はい | C2: 「いいえ」にすると、このセクションと左メニューの項目を削除します。
A3: セクション名 | B3: プロフィール | C3: 名称を変える場合だけ編集してください。ページ見出しと左メニューの名称を同じ内容に変更します。
A5: セクション判定 | C5: =IF(B2="いいえ","削除予定",IF(COUNTIF(C10:C12,"要編集")+COUNTIF(C10:C12,"未入力")+COUNTIF(C16:C20,"要編集")+COUNTIF(C16:C20,"未入力")+COUNTIF(E24:E53,"要編集")+COUNTIF(E24:E53,"未入力")>0,"ERROR: 要編集あり","OK")) -> ERROR: 要編集あり
A7: 経歴・受賞歴・所属学会などの「区分」は自由に変更できます。不要な行は空欄にしてください。下の予備行もそのまま使えます。
A9: 基本情報 | B9: 入力内容 | C9: 判定 | D9: 補足
A10: 肩書 | B10: 教授 | C10: =IF($B$2="いいえ","削除予定",IF(B10="","未入力",IF(B10="教授","要編集","OK"))) -> 要編集
A11: 氏名（日本語） | B11: 佐藤 太郎 | C11: =IF($B$2="いいえ","削除予定",IF(B11="","未入力",IF(B11="佐藤 太郎","要編集","OK"))) -> 要編集
A12: 氏名（英語） | B12: Sato Taro | C12: =IF($B$2="いいえ","削除予定",IF(B12="","未入力",IF(B12="Sato Taro","要編集","OK"))) -> 要編集
A15: 外部リンク名 | B15: URL | C15: 判定 | D15: 補足
A16: 帝都大学研究者紹介 | C16: =IF($B$2="いいえ","削除予定",IF(AND(A16="",B16=""),"削除予定",IF(A16="帝都大学研究者紹介","要編集",IF(OR(A16="",B16=""),"未入力","OK")))) -> 要編集 | D16: 不要な行は名称とURLを両方空欄にします。
A17: Google Scholar | C17: =IF($B$2="いいえ","削除予定",IF(AND(A17="",B17=""),"削除予定",IF(AND(A17="Google Scholar",B17=""),"要編集",IF(OR(A17="",B17=""),"未入力","OK")))) -> 要編集 | D17: 不要な行は名称とURLを両方空欄にします。
C18: =IF($B$2="いいえ","削除予定",IF(AND(A18="",B18=""),"削除予定",IF(OR(A18="",B18=""),"未入力","OK"))) -> 削除予定 | D18: 不要な行は名称とURLを両方空欄にします。
C19: =IF($B$2="いいえ","削除予定",IF(AND(A19="",B19=""),"削除予定",IF(OR(A19="",B19=""),"未入力","OK"))) -> 削除予定 | D19: 不要な行は名称とURLを両方空欄にします。
C20: =IF($B$2="いいえ","削除予定",IF(AND(A20="",B20=""),"削除予定",IF(OR(A20="",B20=""),"未入力","OK"))) -> 削除予定 | D20: 不要な行は名称とURLを両方空欄にします。
A23: No. | B23: 区分 | C23: 年 | D23: 内容 | E23: 判定
A24: 1 | B24: 経歴 | C24: 2023 | D24: 帝都大学工学部卒業 | E24: =IF($B$2="いいえ","削除予定",IF(AND(B24="",C24="",D24=""),"削除予定",IF(AND(B24="経歴",C24="2023",D24="帝都大学工学部卒業"),"要編集",IF(OR(B24="",D24=""),"未入力","OK")))) -> 要編集
A25: 2 | B25: 経歴 | C25: 2023 | D25: 帝都大学大学院工学研究科博士前期課程入学 | E25: =IF($B$2="いいえ","削除予定",IF(AND(B25="",C25="",D25=""),"削除予定",IF(AND(B25="経歴",C25="2023",D25="帝都大学大学院工学研究科博士前期課程入学"),"要編集",IF(OR(B25="",D25=""),"未入力","OK")))) -> 要編集
A26: 3 | B26: 経歴 | C26: 2023 | D26: 帝都大学大学院工学研究科博士前期課程修了 | E26: =IF($B$2="いいえ","削除予定",IF(AND(B26="",C26="",D26=""),"削除予定",IF(AND(B26="経歴",C26="2023",D26="帝都大学大学院工学研究科博士前期課程修了"),"要編集",IF(OR(B26="",D26=""),"未入力","OK")))) -> 要編集
A27: 4 | B27: 経歴 | C27: 2023 | D27: 帝都大学大学院工学研究科博士後期課程入学 | E27: =IF($B$2="いいえ","削除予定",IF(AND(B27="",C27="",D27=""),"削除予定",IF(AND(B27="経歴",C27="2023",D27="帝都大学大学院工学研究科博士後期課程入学"),"要編集",IF(OR(B27="",D27=""),"未入力","OK")))) -> 要編集
A28: 5 | B28: 経歴 | C28: 2023 | D28: 帝都大学大学院工学研究科博士後期課程修了 | E28: =IF($B$2="いいえ","削除予定",IF(AND(B28="",C28="",D28=""),"削除予定",IF(AND(B28="経歴",C28="2023",D28="帝都大学大学院工学研究科博士後期課程修了"),"要編集",IF(OR(B28="",D28=""),"未入力","OK")))) -> 要編集
A29: 6 | B29: 経歴 | C29: 2023 | D29: ABCテクノロジー株式会社 研究員 | E29: =IF($B$2="いいえ","削除予定",IF(AND(B29="",C29="",D29=""),"削除予定",IF(AND(B29="経歴",C29="2023",D29="ABCテクノロジー株式会社 研究員"),"要編集",IF(OR(B29="",D29=""),"未入力","OK")))) -> 要編集
A30: 7 | B30: 経歴 | C30: 2023 | D30: 帝都大学 准教授 | E30: =IF($B$2="いいえ","削除予定",IF(AND(B30="",C30="",D30=""),"削除予定",IF(AND(B30="経歴",C30="2023",D30="帝都大学 准教授"),"要編集",IF(OR(B30="",D30=""),"未入力","OK")))) -> 要編集
A31: 8 | B31: 経歴 | C31: 2023 | D31: 帝都大学 教授 | E31: =IF($B$2="いいえ","削除予定",IF(AND(B31="",C31="",D31=""),"削除予定",IF(AND(B31="経歴",C31="2023",D31="帝都大学 教授"),"要編集",IF(OR(B31="",D31=""),"未入力","OK")))) -> 要編集
A32: 9 | B32: 受賞歴 | C32: 2023 | D32: 日本データサイエンス賞受賞 | E32: =IF($B$2="いいえ","削除予定",IF(AND(B32="",C32="",D32=""),"削除予定",IF(AND(B32="受賞歴",C32="2023",D32="日本データサイエンス賞受賞"),"要編集",IF(OR(B32="",D32=""),"未入力","OK")))) -> 要編集
A33: 10 | B33: 受賞歴 | C33: 2023 | D33: 国際AI学会最優秀論文賞 | E33: =IF($B$2="いいえ","削除予定",IF(AND(B33="",C33="",D33=""),"削除予定",IF(AND(B33="受賞歴",C33="2023",D33="国際AI学会最優秀論文賞"),"要編集",IF(OR(B33="",D33=""),"未入力","OK")))) -> 要編集
A34: 11 | B34: 所属学会 | D34: 全国人工知能研究学会 | E34: =IF($B$2="いいえ","削除予定",IF(AND(B34="",C34="",D34=""),"削除予定",IF(AND(B34="所属学会",C34="",D34="全国人工知能研究学会"),"要編集",IF(OR(B34="",D34=""),"未入力","OK")))) -> 要編集
A35: 12 | B35: 所属学会 | D35: アジア人工知能技術学会 | E35: =IF($B$2="いいえ","削除予定",IF(AND(B35="",C35="",D35=""),"削除予定",IF(AND(B35="所属学会",C35="",D35="アジア人工知能技術学会"),"要編集",IF(OR(B35="",D35=""),"未入力","OK")))) -> 要編集
A36: 13 | B36: 所属学会 | D36: 先端AIイノベーション学会 | E36: =IF($B$2="いいえ","削除予定",IF(AND(B36="",C36="",D36=""),"削除予定",IF(AND(B36="所属学会",C36="",D36="先端AIイノベーション学会"),"要編集",IF(OR(B36="",D36=""),"未入力","OK")))) -> 要編集
A37: 14 | E37: =IF($B$2="いいえ","削除予定",IF(AND(B37="",C37="",D37=""),"削除予定",IF(OR(B37="",D37=""),"未入力","OK"))) -> 削除予定
A38: 15 | E38: =IF($B$2="いいえ","削除予定",IF(AND(B38="",C38="",D38=""),"削除予定",IF(OR(B38="",D38=""),"未入力","OK"))) -> 削除予定
A39: 16 | E39: =IF($B$2="いいえ","削除予定",IF(AND(B39="",C39="",D39=""),"削除予定",IF(OR(B39="",D39=""),"未入力","OK"))) -> 削除予定
A40: 17 | E40: =IF($B$2="いいえ","削除予定",IF(AND(B40="",C40="",D40=""),"削除予定",IF(OR(B40="",D40=""),"未入力","OK"))) -> 削除予定
A41: 18 | E41: =IF($B$2="いいえ","削除予定",IF(AND(B41="",C41="",D41=""),"削除予定",IF(OR(B41="",D41=""),"未入力","OK"))) -> 削除予定
A42: 19 | E42: =IF($B$2="いいえ","削除予定",IF(AND(B42="",C42="",D42=""),"削除予定",IF(OR(B42="",D42=""),"未入力","OK"))) -> 削除予定
A43: 20 | E43: =IF($B$2="いいえ","削除予定",IF(AND(B43="",C43="",D43=""),"削除予定",IF(OR(B43="",D43=""),"未入力","OK"))) -> 削除予定
A44: 21 | E44: =IF($B$2="いいえ","削除予定",IF(AND(B44="",C44="",D44=""),"削除予定",IF(OR(B44="",D44=""),"未入力","OK"))) -> 削除予定
A45: 22 | E45: =IF($B$2="いいえ","削除予定",IF(AND(B45="",C45="",D45=""),"削除予定",IF(OR(B45="",D45=""),"未入力","OK"))) -> 削除予定
A46: 23 | E46: =IF($B$2="いいえ","削除予定",IF(AND(B46="",C46="",D46=""),"削除予定",IF(OR(B46="",D46=""),"未入力","OK"))) -> 削除予定
A47: 24 | E47: =IF($B$2="いいえ","削除予定",IF(AND(B47="",C47="",D47=""),"削除予定",IF(OR(B47="",D47=""),"未入力","OK"))) -> 削除予定
...

Sheet 07_論文・研究発表
A1: 研究室HP 入力データ｜論文・研究発表
A2: このセクションを表示する | B2: はい | C2: 「いいえ」にすると、このセクションと左メニューの項目を削除します。
A3: セクション名 | B3: 論文・研究発表 | C3: 名称を変える場合だけ編集してください。ページ見出しと左メニューの名称を同じ内容に変更します。
A5: セクション判定 | C5: =IF(B2="いいえ","削除予定",IF(COUNTIF(E18:E67,"要編集")+COUNTIF(E18:E67,"未入力")>0,"ERROR: 要編集あり","OK")) -> ERROR: 要編集あり
A7: 分類名は下の「分類設定」で変更します。分類を使わない場合は「表示する」を「いいえ」にしてください。その分類のタブ・左メニュー内の項目・対応する一覧をまとめて削除します。名称を変えれば、タブと左メニュー内の名称も同じ内容に変更します。
A9: 分類No. | B9: 表示する | C9: 分類名 | D9: 補足
A10: 1 | B10: はい | C10: 論文誌 | D10: 名称変更はこのセルだけで構いません。
A11: 2 | B11: はい | C11: 学会発表 | D11: 名称変更はこのセルだけで構いません。
A12: 3 | B12: はい | C12: 外部記事 | D12: 名称変更はこのセルだけで構いません。
A13: 4 | B13: はい | C13: 書籍 | D13: 名称変更はこのセルだけで構いません。
A14: 5 | B14: はい | C14: その他 | D14: 名称変更はこのセルだけで構いません。
A17: 分類 | B17: No. | C17: 本文 | D17: 外部リンクURL | E17: 判定
A18: =$C$10 -> 論文誌 | B18: 1 | C18: 佐藤 太郎, 佐藤真理子, 吉田章: 「組み込みシステムにおける人工知能の応用と性能改善」, 全国人工知能研究学会論文誌, 第39巻2号, (2024). | E18: =IF(OR($B$2="いいえ",$B$10="いいえ"),"削除予定",IF(AND(C18="",D18=""),"削除予定",IF(C18="佐藤 太郎, 佐藤真理子, 吉田章: 「組み込みシステムにおける人工知能の応用と性能改善」, 全国人工知能研究学会論文誌, 第39巻2号, (2024).","要編集",IF(C18="","未入力","OK")))) -> 要編集
A19: =$C$10 -> 論文誌 | B19: 2 | C19: 論文誌_リスト | E19: =IF(OR($B$2="いいえ",$B$10="いいえ"),"削除予定",IF(AND(C19="",D19=""),"削除予定",IF(C19="論文誌_リスト","要編集",IF(C19="","未入力","OK")))) -> 要編集
A20: =$C$10 -> 論文誌 | B20: 3 | C20: 論文誌_リスト | E20: =IF(OR($B$2="いいえ",$B$10="いいえ"),"削除予定",IF(AND(C20="",D20=""),"削除予定",IF(C20="論文誌_リスト","要編集",IF(C20="","未入力","OK")))) -> 要編集
A21: =$C$10 -> 論文誌 | B21: 4 | C21: 論文誌_リスト | E21: =IF(OR($B$2="いいえ",$B$10="いいえ"),"削除予定",IF(AND(C21="",D21=""),"削除予定",IF(C21="論文誌_リスト","要編集",IF(C21="","未入力","OK")))) -> 要編集
A22: =$C$10 -> 論文誌 | B22: 5 | C22: 論文誌_リスト | E22: =IF(OR($B$2="いいえ",$B$10="いいえ"),"削除予定",IF(AND(C22="",D22=""),"削除予定",IF(C22="論文誌_リスト","要編集",IF(C22="","未入力","OK")))) -> 要編集
A23: =$C$10 -> 論文誌 | B23: 6 | C23: 論文誌_リスト | E23: =IF(OR($B$2="いいえ",$B$10="いいえ"),"削除予定",IF(AND(C23="",D23=""),"削除予定",IF(C23="論文誌_リスト","要編集",IF(C23="","未入力","OK")))) -> 要編集
A24: =$C$10 -> 論文誌 | B24: 7 | C24: 論文誌_リスト | E24: =IF(OR($B$2="いいえ",$B$10="いいえ"),"削除予定",IF(AND(C24="",D24=""),"削除予定",IF(C24="論文誌_リスト","要編集",IF(C24="","未入力","OK")))) -> 要編集
A25: =$C$10 -> 論文誌 | B25: 8 | E25: =IF(OR($B$2="いいえ",$B$10="いいえ"),"削除予定",IF(AND(C25="",D25=""),"削除予定",IF(C25="","未入力","OK"))) -> 削除予定
A26: =$C$10 -> 論文誌 | B26: 9 | E26: =IF(OR($B$2="いいえ",$B$10="いいえ"),"削除予定",IF(AND(C26="",D26=""),"削除予定",IF(C26="","未入力","OK"))) -> 削除予定
A27: =$C$10 -> 論文誌 | B27: 10 | E27: =IF(OR($B$2="いいえ",$B$10="いいえ"),"削除予定",IF(AND(C27="",D27=""),"削除予定",IF(C27="","未入力","OK"))) -> 削除予定
A28: =$C$11 -> 学会発表 | B28: 1 | C28: 学会発表_リスト | E28: =IF(OR($B$2="いいえ",$B$11="いいえ"),"削除予定",IF(AND(C28="",D28=""),"削除予定",IF(C28="学会発表_リスト","要編集",IF(C28="","未入力","OK")))) -> 要編集
A29: =$C$11 -> 学会発表 | B29: 2 | C29: 学会発表_リスト | E29: =IF(OR($B$2="いいえ",$B$11="いいえ"),"削除予定",IF(AND(C29="",D29=""),"削除予定",IF(C29="学会発表_リスト","要編集",IF(C29="","未入力","OK")))) -> 要編集
A30: =$C$11 -> 学会発表 | B30: 3 | C30: 学会発表_リスト | E30: =IF(OR($B$2="いいえ",$B$11="いいえ"),"削除予定",IF(AND(C30="",D30=""),"削除予定",IF(C30="学会発表_リスト","要編集",IF(C30="","未入力","OK")))) -> 要編集
A31: =$C$11 -> 学会発表 | B31: 4 | C31: 学会発表_リスト | E31: =IF(OR($B$2="いいえ",$B$11="いいえ"),"削除予定",IF(AND(C31="",D31=""),"削除予定",IF(C31="学会発表_リスト","要編集",IF(C31="","未入力","OK")))) -> 要編集
A32: =$C$11 -> 学会発表 | B32: 5 | C32: 学会発表_リスト | E32: =IF(OR($B$2="いいえ",$B$11="いいえ"),"削除予定",IF(AND(C32="",D32=""),"削除予定",IF(C32="学会発表_リスト","要編集",IF(C32="","未入力","OK")))) -> 要編集
A33: =$C$11 -> 学会発表 | B33: 6 | C33: 学会発表_リスト | E33: =IF(OR($B$2="いいえ",$B$11="いいえ"),"削除予定",IF(AND(C33="",D33=""),"削除予定",IF(C33="学会発表_リスト","要編集",IF(C33="","未入力","OK")))) -> 要編集
A34: =$C$11 -> 学会発表 | B34: 7 | C34: 学会発表_リスト | E34: =IF(OR($B$2="いいえ",$B$11="いいえ"),"削除予定",IF(AND(C34="",D34=""),"削除予定",IF(C34="学会発表_リスト","要編集",IF(C34="","未入力","OK")))) -> 要編集
A35: =$C$11 -> 学会発表 | B35: 8 | C35: 学会発表_リスト | E35: =IF(OR($B$2="いいえ",$B$11="いいえ"),"削除予定",IF(AND(C35="",D35=""),"削除予定",IF(C35="学会発表_リスト","要編集",IF(C35="","未入力","OK")))) -> 要編集
A36: =$C$11 -> 学会発表 | B36: 9 | C36: 学会発表_リスト | E36: =IF(OR($B$2="いいえ",$B$11="いいえ"),"削除予定",IF(AND(C36="",D36=""),"削除予定",IF(C36="学会発表_リスト","要編集",IF(C36="","未入力","OK")))) -> 要編集
A37: =$C$11 -> 学会発表 | B37: 10 | C37: 学会発表_リスト | E37: =IF(OR($B$2="いいえ",$B$11="いいえ"),"削除予定",IF(AND(C37="",D37=""),"削除予定",IF(C37="学会発表_リスト","要編集",IF(C37="","未入力","OK")))) -> 要編集
A38: =$C$12 -> 外部記事 | B38: 1 | C38: 外部記事_リスト | E38: =IF(OR($B$2="いいえ",$B$12="いいえ"),"削除予定",IF(AND(C38="",D38=""),"削除予定",IF(C38="外部記事_リスト","要編集",IF(C38="","未入力","OK")))) -> 要編集
A39: =$C$12 -> 外部記事 | B39: 2 | C39: 外部記事_リスト | E39: =IF(OR($B$2="いいえ",$B$12="いいえ"),"削除予定",IF(AND(C39="",D39=""),"削除予定",IF(C39="外部記事_リスト","要編集",IF(C39="","未入力","OK")))) -> 要編集
A40: =$C$12 -> 外部記事 | B40: 3 | C40: 外部記事_リスト | E40: =IF(OR($B$2="いいえ",$B$12="いいえ"),"削除予定",IF(AND(C40="",D40=""),"削除予定",IF(C40="外部記事_リスト","要編集",IF(C40="","未入力","OK")))) -> 要編集
A41: =$C$12 -> 外部記事 | B41: 4 | C41: 外部記事_リスト | E41: =IF(OR($B$2="いいえ",$B$12="いいえ"),"削除予定",IF(AND(C41="",D41=""),"削除予定",IF(C41="外部記事_リスト","要編集",IF(C41="","未入力","OK")))) -> 要編集
A42: =$C$12 -> 外部記事 | B42: 5 | C42: 外部記事_リスト | E42: =IF(OR($B$2="いいえ",$B$12="いいえ"),"削除予定",IF(AND(C42="",D42=""),"削除予定",IF(C42="外部記事_リスト","要編集",IF(C42="","未入力","OK")))) -> 要編集
A43: =$C$12 -> 外部記事 | B43: 6 | C43: 外部記事_リスト | E43: =IF(OR($B$2="いいえ",$B$12="いいえ"),"削除予定",IF(AND(C43="",D43=""),"削除予定",IF(C43="外部記事_リスト","要編集",IF(C43="","未入力","OK")))) -> 要編集
A44: =$C$12 -> 外部記事 | B44: 7 | C44: 外部記事_リスト | E44: =IF(OR($B$2="いいえ",$B$12="いいえ"),"削除予定",IF(AND(C44="",D44=""),"削除予定",IF(C44="外部記事_リスト","要編集",IF(C44="","未入力","OK")))) -> 要編集
A45: =$C$12 -> 外部記事 | B45: 8 | C45: 外部記事_リスト | E45: =IF(OR($B$2="いいえ",$B$12="いいえ"),"削除予定",IF(AND(C45="",D45=""),"削除予定",IF(C45="外部記事_リスト","要編集",IF(C45="","未入力","OK")))) -> 要編集
...

Sheet 08_Contact
A1: 研究室HP 入力データ｜Contact
A2: このセクションを表示する | B2: はい | C2: 「いいえ」にすると、このセクションと左メニューの項目を削除します。
A3: セクション名 | B3: Contact | C3: 名称を変える場合だけ編集してください。ページ見出しと左メニューの名称を同じ内容に変更します。
A5: セクション判定 | C5: =IF(B2="いいえ","削除予定",IF(COUNTIF(C10:C13,"要編集")+COUNTIF(C10:C13,"未入力")+COUNTIF(C17:C18,"要編集")+COUNTIF(C17:C18,"未入力")>0,"ERROR: 要編集あり","OK")) -> ERROR: 要編集あり
A7: Contact自体が不要なら「このセクションを表示する」を「いいえ」にしてください。Google Mapだけ非表示にすることもできます。
A9: 項目 | B9: 入力内容 | C9: 判定 | D9: 補足
A10: 募集・問い合わせ文 | B10: 「コミュニケーションデザインラボ - 佐藤研究室」では学生の研究生を募集しています。興味がある方はお気軽にご連絡ください。 | C10: =IF($B$2="いいえ","削除予定",IF(B10="","未入力",IF(B10="「コミュニケーションデザインラボ - 佐藤研究室」では学生の研究生を募集しています。興味がある方はお気軽にご連絡ください。","要編集","OK"))) -> 要編集 | D10: 問い合わせ文。
A11: メールアドレス | B11: sample@test.co.jp | C11: =IF($B$2="いいえ","削除予定",IF(B11="","未入力",IF(B11="sample@test.co.jp","要編集","OK"))) -> 要編集 | D11: 公開問い合わせ先。
A12: 郵便番号 | B12: 〒000-0000 | C12: =IF($B$2="いいえ","削除予定",IF(B12="","未入力",IF(B12="〒000-0000","要編集","OK"))) -> 要編集
A13: 住所 | B13: 東京都千代田区0-0-0帝都大学千代田キャンパス3号館201号室 | C13: =IF($B$2="いいえ","削除予定",IF(B13="","未入力",IF(B13="東京都千代田区0-0-0帝都大学千代田キャンパス3号館201号室","要編集","OK"))) -> 要編集
A16: Google Map設定 | B16: 入力内容 | C16: 判定 | D16: 説明
A17: Google Mapを表示する | B17: はい | C17: =IF($B$2="いいえ","削除予定","OK") -> OK | D17: 地図が不要なら「いいえ」にします。
A18: Google Map埋め込みHTML | B18: ここにGoogle Mapの「HTMLをコピー」で取得したiframeを貼り付けてください | C18: =IF(OR($B$2="いいえ",$B$17="いいえ"),"削除予定",IF(B18="","未入力",IF(B18="ここにGoogle Mapの「HTMLをコピー」で取得したiframeを貼り付けてください","要編集","OK"))) -> 要編集 | D18: Google Mapの共有 → 地図を埋め込む → HTMLをコピー、で取得した内容をそのまま貼り付けます。
A21: Google Map 設定手順
A22: 1. Google Mapsで研究室の場所を表示します。 2. 「共有」を押し、「地図を埋め込む」を選びます。 3. 「HTMLをコピー」を押します。 4. コピーした <iframe ...></iframe> 全体を上の「Google Map埋め込みHTML」に貼り付けます。
A27: Google Maps | B27: https://www.google.com/maps

Sheet 09_フッター
A1: 研究室HP 入力データ｜フッター
A2: コピーライトの研究室名を差し替えてください。
A4: セクション判定 | C4: =IF(OR(C7="要編集",C7="未入力"),"ERROR: 要編集あり","OK") -> ERROR: 要編集あり
A6: 項目 | B6: 入力内容 | C6: 判定 | D6: 補足
A7: コピーライト | B7: Copyright (C) 研究室名. All Rights Reserved. | C7: =IF(B7="","未入力",IF(B7="Copyright (C) 研究室名. All Rights Reserved.","要編集","OK")) -> 要編集 | D7: 研究室名を差し替えます。
